[TOC]

# 错误error
### 1. error类型
在GO中错误用内建的 error 类型来表示。error类型是一个有Error方法的接口。Error方法返回一个包含错误信息的字符串。

```
type error interface{
    Error() string
}
```

Errors包提供了快速生成错误值的方法。

```
package main

import "errors"

// errors.New() 使用指定的字符串生成一个错误值
func demo() error {
    return errors.New("a error")
}
```

fmt包中的Errorf方法可以通过格式化字符串返回一个包含指定字符串的错误


```
const name, id = "bimmler", 17

err := fmt.Errorf("user %q (id %d) not found", name, id)

```


### 2. 以go的方式处理错误
GO中没有Exception体系，所有的错误都通过返回值直接返回给调用者。因为GO支持多值返回函数，所以error值通常放在最后一个返回值返回。

不要忽略错误，所有的错误都应该被处理。

```
func demo() (int, error) {
    return 0, error.New("error")
}
```


### 3. 自定义Error类型
错误类型可以包含更多的错误信息，不仅限于一个错误信息的字符串。

```
type MyError struct{
    error string
    code int
}

func (me *MyError)Error() string {
    return me.error
}

func throwError() error {
    return &MyError{error: "错了", code:1}
}
```

### 4. 通过断言获取低层错误类型值
当底层返回错误时如何处理，如何知道具体的错误类型呢？

通过类型断言可以获取底层错误类型

```
package tool

type ArgumentError {
    Name string
}

func (ae *ArgumentError)Error() string {
    return ae.Name + " error"
}

func Div(d1, d2 int) (int, error) {
    if d2 <= 0 {
        return 0, &ArgumentError{name: "d2"}
    }
    return d1 / d2, nil
}

package main

import "tool"
import "fmt"

func main() {
    value, error := tool.Div(10, 0)
    if error == nil {
        fmt.Println(value)
    }
    
    // 通过类型断言获取错误类型
    switch error.(type) {
        case *ArgumentError:
            fmt.Println()
    }
}

```


# panic和recover
### panic
panic是一种严重错误，导致程序无法继续执行。

运行时错误会引起panic, 例如数组越界。通过调用内置函数Panic也可以引起panic错误。

当程序panic后会终止运行，在执行完所有的延迟函数后，程序控制返回到该函数的调用方。这样的过程会一直持续下去，直到当前协程的所有函数都返回退出，然后程序会打印出 panic 信息，接着打印出堆栈跟踪（Stack Trace），最后程序终止。
    
```
func main() {
    f(3)
}
func f(x int) {
    fmt.Printf("f(%d)\n", x+0/x) // panics if x == 0
    defer fmt.Printf("defer %d\n", x)
    f(x - 1)
}

// 打印以下信息
f(3)
f(2)
f(1)
defer 1
defer 2
defer 3
```

panic内建函数的签名如下，可以接收任何类型值

```
func panic(v interface{})
```

### recover
recover可以使程序从panic中恢复过来，但是何时应该使用recover建议看官方文档。

http://shouce.jb51.net/gopl-zh/ch5/ch5-10.html


recover函数的的签名如下，可以返回panic时的错误值

```
func recover() interface{}
```

需要注意的是
1. 只有在相同的 Go 协程中调用 recover 才管用。recover 不能恢复一个不同协程的 panic。
2. 只有在延迟函数的内部，调用 recover 才有用。如果在延迟函数的外部调用 recover会返回nil
